When calling 'get_joints_angle' on MyArmC

Traceback (most recent call last):
  File "/home/alex/Space/drive-personal/Projects - In Progress/Project - 2024 - WorldModeling/acton_ai/acton_ai/scripts/validate_robot.py", line 20, in <module>
    main()
  File "/home/alex/Space/drive-personal/Projects - In Progress/Project - 2024 - WorldModeling/acton_ai/acton_ai/scripts/validate_robot.py", line 15, in main
    controller_angles = controller.get_joints_angle()
  File "/home/alex/Space/drive-personal/Projects - In Progress/Project - 2024 - WorldModeling/pymycobot/pymycobot/myarm_api.py", line 204, in get_joints_angle
    return self._mesg(ProtocolCode.GET_ANGLES, has_reply=True)
  File "/home/alex/Space/drive-personal/Projects - In Progress/Project - 2024 - WorldModeling/pymycobot/pymycobot/myarm_api.py", line 67, in _mesg
    data = self._read(genre, command=command, timeout=timeout, _class=self.__class__.__name__)
  File "/home/alex/Space/drive-personal/Projects - In Progress/Project - 2024 - WorldModeling/pymycobot/pymycobot/common.py", line 847, in read
    data = self._serial_port.read()
  File "/home/alex/.cache/pypoetry/virtualenvs/acton-ai-YwqBChkT-py3.10/lib/python3.10/site-packages/serial/serialposix.py", line 595, in read
    raise SerialException(
serial.serialutil.SerialException: device reports readiness to read but returned no data (device disconnected or multiple access on port?)